Workbook

Sheet Supuestos
A2: Tipo de cambio promedio EUR-MXN | B2: =+('EUR A MXN'!G3+'EUR A MXN'!G4)/2 -> 21.626461
A3: Tasa bono español a 10 años | B3: =+('Bono español a 10 años'!J2+'Bono español a 10 años'!J3)/2 -> 0.031682083
A4: Inflación en México | B4: =+('Inflación INEGI'!E5+'Inflación INEGI'!E6)/2 -> 0.047086364
A5: Importaciones de la industria | B5: =185791000000*'Datos Proporcionados CL Circula'!H2 -> 3323243617000 | C5: MXN
A6: Aproximado de contenedores exportados | B6: 2112000
A7: Contenedores que ya tienen CL Circular | B7: =(9000/'Datos Proporcionados CL Circula'!B6)*12 -> 3085.7143 | C7: # numero de sensores en circulación
A8: Participacion potencial de mercado | B8: =+B7/B6 -> 0.001461039
A9: Costos administrativos | B9: 1000 | C9: DLS
A10: Valor de las unidades en circulación | B10: =+B7*'Datos Proporcionados CL Circula'!B5 -> 108000 | C10: DLS
A11: Depreciación por unidad (10 años de vida util) | B11: =+(B10/10)/B7 -> 3.5 | C11: DLS | D11: por año
A12: Finacimiento con casa matriz | B12: =+'Sin Financiamiento'!B29 -> 0
A13: Nueva participacion depues de inversion | B13: =+B7+'Con finacimiento'!P3 -> 4199.7143
B14: =+B13/B6 -> 0.0019885011
A15: Nuevo valor de las unidades en circulación | B15: =+B13*'Datos Proporcionados CL Circula'!B6 -> 146990

Sheet EUR A MXN
A1: 42437
A2: 46089 | B2: #VALUE!
B3: {=+_xlfn.STOCKHISTORY(B2,A1,A2,2,1,0,1)} -> Fecha | C3: Cierre | D3: Dif. % | F3: Promedio | G3: =+AVERAGE(C4:C124) -> 21.698321
B4: 42430 | C4: 19.6596 | F4: Mediana | G4: =+MEDIAN(C4:C124) -> 21.5546
B5: 42461 | C5: 19.6665 | D5: =+(C5-C4)/C4 -> 0.00035097357
B6: 42491 | C6: 20.5513 | D6: =+(C6-C5)/C5 -> 0.044990212 | G6: Mensual | H6: Anual
B7: 42522 | C7: 20.2848 | D7: =+(C7-C6)/C6 -> -0.012967549 | F7: Promedio | G7: =+AVERAGE(D5:D124) -> 0.00088353637 | H7: =+G7*12 -> 0.010602436
B8: 42552 | C8: 20.9455 | D8: =+(C8-C7)/C7 -> 0.032571186
B9: 42583 | C9: 20.9544 | D9: =+(C9-C8)/C8 -> 0.00042491227
B10: 42614 | C10: 21.7736 | D10: =+(C10-C9)/C9 -> 0.039094415
B11: 42644 | C11: 20.7042 | D11: =+(C11-C10)/C10 -> -0.049114524
B12: 42675 | C12: 21.7722 | D12: =+(C12-C11)/C11 -> 0.051583737
B13: 42705 | C13: 21.7777 | D13: =+(C13-C12)/C12 -> 0.00025261572
B14: 42736 | C14: 22.4902 | D14: =+(C14-C13)/C13 -> 0.032716954
B15: 42767 | C15: 21.2558 | D15: =+(C15-C14)/C14 -> -0.054886128
B16: 42795 | C16: 19.936 | D16: =+(C16-C15)/C15 -> -0.062091288
B17: 42826 | C17: 20.4935 | D17: =+(C17-C16)/C16 -> 0.027964486
B18: 42856 | C18: 20.9298 | D18: =+(C18-C17)/C17 -> 0.021289677
B19: 42887 | C19: 20.7017 | D19: =+(C19-C18)/C18 -> -0.010898336
... B124: 46082 | C124: 20.477 | D124: =+(C124-C123)/C123 -> 0.0072207848
A126: Yahoo Finanzas. (s. f.). Precios históricos de acciones y datos de EUR/MXN (EURMXN=X). Recuperado el 8 de marzo de 2026, de https://es-us.finanzas.yahoo.com/quote/EURMXN%3DX/history/

Sheet Datos Proporcionados CL Circula
A1: CLCircular | B1: DLS | C1: MXN | D1: EUR
A2: Costos de transporte por unidad | B2: 3 | C2: =+B2*H2 -> 53.661 | D2: =+B2*H3 -> 2.5818 | G2: DLS-MXN | H2: 17.887 | J2: Google Finance. (s. f.). Tipo de cambio de USD a MXN y noticias relacionadas. Recuperado el 8 de marzo de 2026, de https://www.google.com/finance/quote/USD-MXN?hl=es
A3: Costos de comunicación por unidad | B3: 1 | C3: =+B3*H2 -> 17.887 | D3: =+B3*H3 -> 0.8606 | G3: DLS-EUR | H3: 0.8606 | J3: Google Finance. (s. f.). Tipo de cambio de USD a EUR y noticias relacionadas. Recuperado el 8 de marzo de 2026, de https://www.google.com/finance/quote/USD-EUR?hl=es
A4: % de unidades perdidas | B4: 0.15 | C4: =+B4 -> 0.15 | D4: =+C4 -> 0.15
A5: Costo de manufactura por unidad | B5: 35 | C5: =+B5*H2 -> 626.045 | D5: =+B5*H3 -> 30.121
A6: Precio de venta por viaje | B6: 35 | C6: =+B6*H2 -> 626.045 | D6: =+B6*H3 -> 30.121
A7: Viajes por dispositivo al año | B7: 6 | C7: =+B7 -> 6 | D7: =+C7 -> 6
A9: Dispositivos ODM
A10: Precio de venta por viaje | B10: 15 | C10: =+B10*H2 -> 268.305 | D10: =+B10*H3 -> 12.909
A11: % de margen neto | B11: 0.2 | C11: =+B11 -> 0.2 | D11: =+C11 -> 0.2
A13: Comisiones de distribuidores ODM % | B13: 0.1 | C13: =+B13 -> 0.1 | D13: =+C13 -> 0.1
A15: Productos Ozeano
A16: % de margen neto | B16: 0.2 | C16: =+B16 -> 0.2 | D16: =+C16 -> 0.2
A18: Acum margin Ozeano
A20: CLCircular
A21: TOTAL COMMUNICATION COSTS
A22: SPAIN-GLOBAL
A23: TOTAL TRANSPORT COSTS
A24: SPAIN-GLOBAL
A25: COLOMBIA
A26: ECUADOR
A27: MÉXICO
A28: GUATEMALA
A29: PERU
A30: SOUTH AFRICA
... A84: COSTE TRANSPORTE

Sheet Bono español a 10 años
A1: Fecha | B1: Último | C1: Apertura | D1: Máximo | E1: Mínimo | F1: % var.
A2: 01.03.2026 | B2: 3360 | C2: 3139 | D2: 3353 | E2: 3139 | F2: 9,66% | I2: Promedio | J2: =+AVERAGE(B2:B25)/100000 -> 0.031829167
A3: 01.02.2026 | B3: 3064 | C3: 3230 | D3: 3252 | E3: 3062 | F3: -4,64% | I3: Mediana | J3: =+MEDIAN(B2:B25)/100000 -> 0.031535
A4: 01.01.2026 | B4: 3213 | C4: 3335 | D4: 3335 | E4: 3199 | F4: -2,40%
A5: 01.12.2025 | B5: 3292 | C5: 3226 | D5: 3339 | E5: 3218 | F5: 3,98%
A6: 01.11.2025 | B6: 3166 | C6: 3165 | D6: 3224 | E6: 3139 | F6: 0,80%
A7: 01.10.2025 | B7: 3141 | C7: 3248 | D7: 3257 | E7: 3082 | F7: -3,59%
A8: 01.09.2025 | B8: 3258 | C8: 3350 | D8: 3402 | E8: 3224 | F8: -2,16%
A9: 01.08.2025 | B9: 3330 | C9: 3262 | D9: 3364 | E9: 3200 | F9: 1,83%
A10: 01.07.2025 | B10: 3270 | C10: 3215 | D10: 3341 | E10: 3197 | F10: 0,74%
A11: 01.06.2025 | B11: 3246 | C11: 3114 | D11: 3246 | E11: 3080 | F11: 4,81%
A12: 01.05.2025 | B12: 3097 | C12: 3181 | D12: 3318 | E12: 3096 | F12: -0,48%
A13: 01.04.2025 | B13: 3112 | C13: 3311 | D13: 3349 | E13: 3089 | F13: -7,48%
A14: 01.03.2025 | B14: 3364 | C14: 3152 | D14: 3524 | E14: 3152 | F14: 8,99%
A15: 01.02.2025 | B15: 3086 | C15: 3057 | D15: 3216 | E15: 3030 | F15: -0,87%
... A25: 01.04.2024 | B25: 3351 | C25: 3221 | D25: 3454 | E25: 3146 | F25: 6,28%
A27: Investing.com. (s. f.). Rendimiento del Bono español a 10 años. Recuperado el 8 de marzo de 2026, de https://es.investing.com/rates-bonds/spain-10-year-bond-yield-historical-data

Sheet Inflación INEGI
A1: Instituto Nacional de Estadística y Geografía (INEGI)
A2: Fuente:
A3: /f1 INEGI. Índice Nacional de Precios al Consumidor (INPC).
A5: 2016/01 | B5: 2.61 | D5: Promedio | E5: =+AVERAGE(B5:B125)/100 -> 0.048372727
A6: 2016/02 | B6: 2.87 | D6: Mediana | E6: =+MEDIAN(B5:B125)/100 -> 0.0458
A7: 2016/03 | B7: 2.6
A8: 2016/04 | B8: 2.54
A9: 2016/05 | B9: 2.6
A10: 2016/06 | B10: 2.54
A11: 2016/07 | B11: 2.65
A12: 2016/08 | B12: 2.73
A13: 2016/09 | B13: 2.97
A14: 2016/10 | B14: 3.06
A15: 2016/11 | B15: 3.31
A16: 2016/12 | B16: 3.36
A17: 2017/01 | B17: 4.72
A18: 2017/02 | B18: 4.86
... A125: 2026/01 | B125: 3.79

Sheet Industria Automotriz
B2: Exportaciones
B3: Industria | C3: Valor de las exportaciones
B4: Automotriz | C4: =+Supuestos!B5 -> 3323243617000
B7: Año | C7: Crecimiento en pesos de las exportaciones | D7: Escenarios | G7: Año | H7: Crecimiento en numero de contenedores de las exportaciones | I7: Escenarios
D8: Bajo | E8: Alto | I8: Bajo | J8: Alto
B9: 2025 | C9: =+C4 -> 3323243617000 | D9: 0.5 | E9: 1.5 | G9: 2025 | H9: =+Supuestos!B6 -> 2112000 | I9: 0.5 | J9: 1.5
B10: 2026 | C10: =+C9*(1+Supuestos!$B$4) -> 3.4797231e+12 | D10: =+C9*(1+(Supuestos!$B$4*'Industria Automotriz'!$D$9)) -> 3.4014833e+12 | E10: =+C9*(1+(Supuestos!B4*'Industria Automotriz'!E9)) -> 3.5579628e+12 | G10: 2026 | H10: =+H9*(1+Supuestos!$B$4) -> 2211446.4 | I10: =+H9*(1+(Supuestos!$B$4*'Industria Automotriz'!$D$9)) -> 2161723.2 | J10: =+H9*(1+(Supuestos!G4*'Industria Automotriz'!J9)) -> 2112000
B11: 2027 | C11: =+C10*(1+Supuestos!$B$4) -> 3.6435706e+12 | D11: =+D10*(1+(Supuestos!$B$4*'Industria Automotriz'!$D$9)) -> 3.4815651e+12 | E11: =+E10*(1+(Supuestos!$B$4*'Industria Automotriz'!$E$9)) -> 3.8092601e+12 | G11: 2027 | H11: =+H10*(1+Supuestos!$B$4) -> 2315575.4 | I11: =+I10*(1+(Supuestos!$B$4*'Industria Automotriz'!$D$9)) -> 2212617 | J11: =+J10*(1+(Supuestos!$B$4*'Industria Automotriz'!$E$9)) -> 2261169.6
B12: 2028 | C12: =+C11*(1+Supuestos!$B$4) -> 3.8151331e+12 | D12: =+D11*(1+(Supuestos!$B$4*'Industria Automotriz'!$D$9)) -> 3.5635322e+12 | E12: =+E11*(1+(Supuestos!$B$4*'Industria Automotriz'!$E$9)) -> 4.0783064e+12 | G12: 2028 | H12: =+H11*(1+Supuestos!$B$4) -> 2424607.4 | I12: =+I11*(1+(Supuestos!$B$4*'Industria Automotriz'!$D$9)) -> 2264709.1 | J12: =+J11*(1+(Supuestos!$B$4*'Industria Automotriz'!$E$9)) -> 2420875
B13: 2029 | C13: =+C12*(1+Supuestos!$B$4) -> 3.9947738e+12 | D13: =+D12*(1+(Supuestos!$B$4*'Industria Automotriz'!$D$9)) -> 3.6474291e+12 | E13: =+E12*(1+(Supuestos!$B$4*'Industria Automotriz'!$E$9)) -> 4.3663553e+12 | G13: 2029 | H13: =+H12*(1+Supuestos!$B$4) -> 2538773.3 | I13: =+I12*(1+(Supuestos!$B$4*'Industria Automotriz'!$D$9)) -> 2318027.5 | J13: =+J12*(1+(Supuestos!$B$4*'Industria Automotriz'!$E$9)) -> 2591860.3
B14: 2030 | C14: =+C13*(1+Supuestos!$B$4) -> 4.1828732e+12 | D14: =+D13*(1+(Supuestos!$B$4*'Industria Automotriz'!$D$9)) -> 3.7333012e+12 | E14: =+E13*(1+(Supuestos!$B$4*'Industria Automotriz'!$E$9)) -> 4.674749e+12 | G14: 2030 | H14: =+H13*(1+Supuestos!$B$4) -> 2658314.9 | I14: =+I13*(1+(Supuestos!$B$4*'Industria Automotriz'!$D$9)) -> 2372601.3 | J14: =+J13*(1+(Supuestos!$B$4*'Industria Automotriz'!$E$9)) -> 2774922.2
B15: 2031 | C15: =+C14*(1+Supuestos!$B$4) -> 4.3798295e+12 | D15: =+D14*(1+(Supuestos!$B$4*'Industria Automotriz'!$D$9)) -> 3.821195e+12 | E15: =+E14*(1+(Supuestos!$B$4*'Industria Automotriz'!$E$9)) -> 5.0049244e+12 | G15: 2031 | H15: =+H14*(1+Supuestos!$B$4) -> 2783485.3 | I15: =+I14*(1+(Supuestos!$B$4*'Industria Automotriz'!$D$9)) -> 2428459.9 | J15: =+J14*(1+(Supuestos!$B$4*'Industria Automotriz'!$E$9)) -> 2970913.7
B16: 2032 | C16: =+C15*(1+Supuestos!$B$4) -> 4.5860597e+12 | D16: =+D15*(1+(Supuestos!$B$4*'Industria Automotriz'!$D$9)) -> 3.9111581e+12 | E16: =+E15*(1+(Supuestos!$B$4*'Industria Automotriz'!$E$9)) -> 5.35842e+12 | G16: 2032 | H16: =+H15*(1+Supuestos!$B$4) -> 2914549.5 | I16: =+I15*(1+(Supuestos!$B$4*'Industria Automotriz'!$D$9)) -> 2485633.5 | J16: =+J15*(1+(Supuestos!$B$4*'Industria Automotriz'!$E$9)) -> 3180748
B17: 2033 | C17: =+C16*(1+Supuestos!$B$4) -> 4.8020006e+12 | D17: =+D16*(1+(Supuestos!$B$4*'Industria Automotriz'!$D$9)) -> 4.0032392e+12 | E17: =+E16*(1+(Supuestos!$B$4*'Industria Automotriz'!$E$9)) -> 5.7368827e+12 | G17: 2033 | H17: =+H16*(1+Supuestos!$B$4) -> 3051785.1 | I17: =+I16*(1+(Supuestos!$B$4*'Industria Automotriz'!$D$9)) -> 2544153.3 | J17: =+J16*(1+(Supuestos!$B$4*'Industria Automotriz'!$E$9)) -> 3405402.8
B18: 2034 | C18: =+C17*(1+Supuestos!$B$4) -> 5.0281093e+12 | D18: =+D17*(1+(Supuestos!$B$4*'Industria Automotriz'!$D$9)) -> 4.0974881e+12 | E18: =+E17*(1+(Supuestos!$B$4*'Industria Automotriz'!$E$9)) -> 6.1420762e+12 | G18: 2034 | H18: =+H17*(1+Supuestos!$B$4) -> 3195482.5 | I18: =+I17*(1+(Supuestos!$B$4*'Industria Automotriz'!$D$9)) -> 2604050.7 | J18: =+J17*(1+(Supuestos!$B$4*'Industria Automotriz'!$E$9)) -> 3645924.8
B19: 2035 | C19: =+C18*(1+Supuestos!$B$4) -> 5.2648647e+12 | D19: =+D18*(1+(Supuestos!$B$4*'Industria Automotriz'!$D$9)) -> 4.1939561e+12 | E19: =+E18*(1+(Supuestos!$B$4*'Industria Automotriz'!$E$9)) -> 6.5758882e+12 | G19: 2035 | H19: =+H18*(1+Supuestos!$B$4) -> 3345946.2 | I19: =+I18*(1+(Supuestos!$B$4*'Industria Automotriz'!$D$9)) -> 2665358.4 | J19: =+J18*(1+(Supuestos!$B$4*'Industria Automotriz'!$E$9)) -> 3903434.8
B22: Año | C22: Participacion de mercado | D22: Escenarios | G22: Año | H22: Ventas totales México DLS | I22: Escenarios
D23: Bajo | E23: Alto | I23: Bajo | J23: Alto
B24: 2025 | C24: 0.0015 | D24: 0.5 | E24: 1.5 | G24: 2025 | H24: =9000*12 -> 108000 | I24: 0.5 | J24: 1.5
B25: 2026 | C25: =+C24*(1+Supuestos!$B$4) -> 0.0015706295 | D25: =+C24*(1+(Supuestos!$B$4*'Industria Automotriz'!$D$9)) -> 0.0015353148 | E25: =+C24*(1+(Supuestos!B19*'Industria Automotriz'!E24)) -> 0.0015 | G25: 2026 | H25: =+H24*(1+Supuestos!$B$4) -> 113085.33 | I25: =+H24*(1+(Supuestos!$B$4*'Industria Automotriz'!$D$9)) -> 110542.66 | J25: =+H25*(1+(Supuestos!G19*'Industria Automotriz'!J24)) -> 113085.33
B26: 2027 | C26: =+C25*(1+Supuestos!$B$4) -> 0.0016445848 | D26: =+D25*(1+(Supuestos!$B$4*'Industria Automotriz'!$D$9)) -> 0.001571461 | E26: =+E25*(1+(Supuestos!$B$4*'Industria Automotriz'!$E$9)) -> 0.0016059443 | G26: 2027 | H26: =+H25*(1+Supuestos!$B$4) -> 118410.1 | I26: =+I25*(1+(Supuestos!$B$4*'Industria Automotriz'!$D$9)) -> 113145.19 | J26: =+J25*(1+(Supuestos!$B$4*'Industria Automotriz'!$E$9)) -> 121072.49
B27: 2028 | C27: =+C26*(1+Supuestos!$B$4) -> 0.0017220223 | D27: =+D26*(1+(Supuestos!$B$4*'Industria Automotriz'!$D$9)) -> 0.0016084582 | E27: =+E26*(1+(Supuestos!$B$4*'Industria Automotriz'!$E$9)) -> 0.0017193714 | G27: 2028 | H27: =+H26*(1+Supuestos!$B$4) -> 123985.61 | I27: =+I26*(1+(Supuestos!$B$4*'Industria Automotriz'!$D$9)) -> 115808.99 | J27: =+J26*(1+(Supuestos!$B$4*'Industria Automotriz'!$E$9)) -> 129623.79
B28: 2029 | C28: =+C27*(1+Supuestos!$B$4) -> 0.0018031061 | D28: =+D27*(1+(Supuestos!$B$4*'Industria Automotriz'!$D$9)) -> 0.0016463264 | E28: =+E27*(1+(Supuestos!$B$4*'Industria Automotriz'!$E$9)) -> 0.0018408099 | G28: 2029 | H28: =+H27*(1+Supuestos!$B$4) -> 129823.64 | I28: =+I27*(1+(Supuestos!$B$4*'Industria Automotriz'!$D$9)) -> 118535.5 | J28: =+J27*(1+(Supuestos!$B$4*'Industria Automotriz'!$E$9)) -> 138779.06
B29: 2030 | C29: =+C28*(1+Supuestos!$B$4) -> 0.0018880078 | D29: =+D28*(1+(Supuestos!$B$4*'Industria Automotriz'!$D$9)) -> 0.0016850861 | E29: =+E28*(1+(Supuestos!$B$4*'Industria Automotriz'!$E$9)) -> 0.0019708254 | G29: 2030 | H29: =+H28*(1+Supuestos!$B$4) -> 135936.56 | I29: =+I28*(1+(Supuestos!$B$4*'Industria Automotriz'!$D$9)) -> 121326.2 | J29: =+J28*(1+(Supuestos!$B$4*'Industria Automotriz'!$E$9)) -> 148580.96
B30: 2031 | C30: =+C29*(1+Supuestos!$B$4) -> 0.0019769072 | D30: =+D29*(1+(Supuestos!$B$4*'Industria Automotriz'!$D$9)) -> 0.0017247584 | E30: =+E29*(1+(Supuestos!$B$4*'Industria Automotriz'!$E$9)) -> 0.0021100239 | G30: 2031 | H30: =+H29*(1+Supuestos!$B$4) -> 142337.32 | I30: =+I29*(1+(Supuestos!$B$4*'Industria Automotriz'!$D$9)) -> 124182.61 | J30: =+J29*(1+(Supuestos!$B$4*'Industria Automotriz'!$E$9)) -> 159075.16
B31: 2032 | C31: =+C30*(1+Supuestos!$B$4) -> 0.0020699926 | D31: =+D30*(1+(Supuestos!$B$4*'Industria Automotriz'!$D$9)) -> 0.0017653647 | E31: =+E30*(1+(Supuestos!$B$4*'Industria Automotriz'!$E$9)) -> 0.002259054 | G31: 2032 | H31: =+H30*(1+Supuestos!$B$4) -> 149039.46 | I31: =+I30*(1+(Supuestos!$B$4*'Industria Automotriz'!$D$9)) -> 127106.26 | J31: =+J30*(1+(Supuestos!$B$4*'Industria Automotriz'!$E$9)) -> 170310.57
B32: 2033 | C32: =+C31*(1+Supuestos!$B$4) -> 0.002167461 | D32: =+D31*(1+(Supuestos!$B$4*'Industria Automotriz'!$D$9)) -> 0.001806927 | E32: =+E31*(1+(Supuestos!$B$4*'Industria Automotriz'!$E$9)) -> 0.0024186099 | G32: 2033 | H32: =+H31*(1+Supuestos!$B$4) -> 156057.19 | I32: =+I31*(1+(Supuestos!$B$4*'Industria Automotriz'!$D$9)) -> 130098.75 | J32: =+J31*(1+(Supuestos!$B$4*'Industria Automotriz'!$E$9)) -> 182339.53
B33: 2034 | C33: =+C32*(1+Supuestos!$B$4) -> 0.0022695188 | D33: =+D32*(1+(Supuestos!$B$4*'Industria Automotriz'!$D$9)) -> 0.0018494678 | E33: =+E32*(1+(Supuestos!$B$4*'Industria Automotriz'!$E$9)) -> 0.0025894352 | G33: 2034 | H33: =+H32*(1+Supuestos!$B$4) -> 163405.36 | I33: =+I32*(1+(Supuestos!$B$4*'Industria Automotriz'!$D$9)) -> 133161.69 | J33: =+J32*(1+(Supuestos!$B$4*'Industria Automotriz'!$E$9)) -> 195218.09
B34: 2035 | C34: =+C33*(1+Supuestos!$B$4) -> 0.0023763822 | D34: =+D33*(1+(Supuestos!$B$4*'Industria Automotriz'!$D$9)) -> 0.0018930102 | E34: =+E33*(1+(Supuestos!$B$4*'Industria Automotriz'!$E$9)) -> 0.0027723259 | G34: 2035 | H34: =+H33*(1+Supuestos!$B$4) -> 171099.52 | I34: =+I33*(1+(Supuestos!$B$4*'Industria Automotriz'!$D$9)) -> 136296.73 | J34: =+J33*(1+(Supuestos!$B$4*'Industria Automotriz'!$E$9)) -> 209006.25
B36: Año | C36: Participacion de mercado con fianciamiento | D36: Escenarios | G36: Año | H36: Ventas totales con finaciamiento México DLS | I36: Escenarios
D37: Bajo | E37: Alto | I37: Bajo | J37: Alto
B38: 2025 | C38: =+Supuestos!B14 -> 0.0019885011 | D38: 0.5 | E38: 1.5 | G38: 2025 | H38: =+Supuestos!B15 -> 146990 | I38: 0.5 | J38: 1.5 | L38: 146990
B39: 2026 | C39: =+C38*(1+Supuestos!$B$4) -> 0.0020821324 | D39: =+C38*(1+(Supuestos!$B$4*'Industria Automotriz'!$D$9)) -> 0.0020353167 | E39: =+C38*(1+(Supuestos!B33*'Industria Automotriz'!E38)) -> 0.0019885011 | G39: 2026 | H39: =+H38*(1+Supuestos!$B$4) -> 153911.22 | I39: =+H38*(1+(Supuestos!$B$4*'Industria Automotriz'!$D$9)) -> 150450.61 | J39: =+H39*(1+(Supuestos!G33*'Industria Automotriz'!J38)) -> 153911.22 | L39: 153911.22
B40: 2027 | C40: =+C39*(1+Supuestos!$B$4) -> 0.0021801724 | D40: =+D39*(1+(Supuestos!$B$4*'Industria Automotriz'!$D$9)) -> 0.0020832346 | E40: =+E39*(1+(Supuestos!$B$4*'Industria Automotriz'!$E$9)) -> 0.002128948 | G40: 2027 | H40: =+H39*(1+Supuestos!$B$4) -> 161158.34 | I40: =+I39*(1+(Supuestos!$B$4*'Industria Automotriz'!$D$9)) -> 153992.7 | J40: =+J39*(1+(Supuestos!$B$4*'Industria Automotriz'!$E$9)) -> 164781.9 | L40: 161158.34
B41: 2028 | C41: =+C40*(1+Supuestos!$B$4) -> 0.0022828288 | D41: =+D40*(1+(Supuestos!$B$4*'Industria Automotriz'!$D$9)) -> 0.0021322805 | E41: =+E40*(1+(Supuestos!$B$4*'Industria Automotriz'!$E$9)) -> 0.0022793146 | G41: 2028 | H41: =+H40*(1+Supuestos!$B$4) -> 168746.7 | I41: =+I40*(1+(Supuestos!$B$4*'Industria Automotriz'!$D$9)) -> 157618.18 | J41: =+J40*(1+(Supuestos!$B$4*'Industria Automotriz'!$E$9)) -> 176420.38 | L41: 168746.7
B42: 2029 | C42: =+C41*(1+Supuestos!$B$4) -> 0.0023903189 | D42: =+D41*(1+(Supuestos!$B$4*'Industria Automotriz'!$D$9)) -> 0.0021824812 | E42: =+E41*(1+(Supuestos!$B$4*'Industria Automotriz'!$E$9)) -> 0.0024403016 | G42: 2029 | H42: =+H41*(1+Supuestos!$B$4) -> 176692.37 | I42: =+I41*(1+(Supuestos!$B$4*'Industria Automotriz'!$D$9)) -> 161329.01 | J42: =+J41*(1+(Supuestos!$B$4*'Industria Automotriz'!$E$9)) -> 188880.87 | L42: 176692.37
B43: 2030 | C43: =+C42*(1+Supuestos!$B$4) -> 0.0025028703 | D43: =+D42*(1+(Supuestos!$B$4*'Industria Automotriz'!$D$9)) -> 0.0022338637 | E43: =+E42*(1+(Supuestos!$B$4*'Industria Automotriz'!$E$9)) -> 0.002612659 | G43: 2030 | H43: =+H42*(1+Supuestos!$B$4) -> 185012.17 | I43: =+I42*(1+(Supuestos!$B$4*'Industria Automotriz'!$D$9)) -> 165127.21 | J43: =+J42*(1+(Supuestos!$B$4*'Industria Automotriz'!$E$9)) -> 202221.44 | L43: 185012.17
B44: 2031 | C44: =+C43*(1+Supuestos!$B$4) -> 0.0026207214 | D44: =+D43*(1+(Supuestos!$B$4*'Industria Automotriz'!$D$9)) -> 0.002286456 | E44: =+E43*(1+(Supuestos!$B$4*'Industria Automotriz'!$E$9)) -> 0.0027971899 | G44: 2031 | H44: =+H43*(1+Supuestos!$B$4) -> 193723.73 | I44: =+I43*(1+(Supuestos!$B$4*'Industria Automotriz'!$D$9)) -> 169014.83 | J44: =+J43*(1+(Supuestos!$B$4*'Industria Automotriz'!$E$9)) -> 216504.24 | L44: 193723.73
B45: 2032 | C45: =+C44*(1+Supuestos!$B$4) -> 0.0027441216 | D45: =+D44*(1+(Supuestos!$B$4*'Industria Automotriz'!$D$9)) -> 0.0023402865 | E45: =+E44*(1+(Supuestos!$B$4*'Industria Automotriz'!$E$9)) -> 0.0029947542 | G45: 2032 | H45: =+H44*(1+Supuestos!$B$4) -> 202845.47 | I45: =+I44*(1+(Supuestos!$B$4*'Industria Automotriz'!$D$9)) -> 172993.97 | J45: =+J44*(1+(Supuestos!$B$4*'Industria Automotriz'!$E$9)) -> 231795.84 | L45: 202845.47
B46: 2033 | C46: =+C45*(1+Supuestos!$B$4) -> 0.0028733323 | D46: =+D45*(1+(Supuestos!$B$4*'Industria Automotriz'!$D$9)) -> 0.0023953842 | E46: =+E45*(1+(Supuestos!$B$4*'Industria Automotriz'!$E$9)) -> 0.0032062723 | G46: 2033 | H46: =+H45*(1+Supuestos!$B$4) -> 212396.73 | I46: =+I45*(1+(Supuestos!$B$4*'Industria Automotriz'!$D$9)) -> 177066.8 | J46: =+J45*(1+(Supuestos!$B$4*'Industria Automotriz'!$E$9)) -> 248167.48 | L46: 212396.73
...

Sheet Sin Financiamiento
A1: Estados fiancieros Proyectados
B3: 2025 | C3: 2026 | D3: 2027 | E3: 2028 | F3: 2029 | G3: 2030 | H3: 2031 | I3: 2032 | J3: 2033 | K3: 2034 | L3: 2035
A4: Ingresos Base
A7: Ingreso | B7: =+'Industria Automotriz'!H24 -> 108000 | C7: =+'Industria Automotriz'!H25 -> 113085.33 | D7: =+'Industria Automotriz'!H26 -> 118410.1 | E7: =+'Industria Automotriz'!H27 -> 123985.61 | F7: =+'Industria Automotriz'!H28 -> 129823.64 | G7: =+'Industria Automotriz'!H29 -> 135936.56 | H7: =+'Industria Automotriz'!H30 -> 142337.32 | I7: =+'Industria Automotriz'!H31 -> 149039.46 | J7: =+'Industria Automotriz'!H32 -> 156057.19 | K7: =+'Industria Automotriz'!H33 -> 163405.36 | L7: =+'Industria Automotriz'!H34 -> 171099.52
A8: Costo de Venta | B8: =+B7*0.8 -> 86400 | C8: =+C7*0.8 -> 90468.262 | D8: =+D7*0.8 -> 94728.083 | E8: =+E7*0.8 -> 99188.484 | F8: =+F7*0.8 -> 103858.91 | G8: =+G7*0.8 -> 108749.25 | H8: =+H7*0.8 -> 113869.85 | I8: =+I7*0.8 -> 119231.57 | ... L8: =+L7*0.8 -> 136879.62
A9: Margen bruto | B9: =+B7-B8 -> 21600 | C9: =+C7-C8 -> 22617.065 | D9: =+D7-D8 -> 23682.021 | E9: =+E7-E8 -> 24797.121 | F9: =+F7-F8 -> 25964.727 | G9: =+G7-G8 -> 27187.312 | H9: =+H7-H8 -> 28467.464 | I9: =+I7-I8 -> 29807.893 | ... L9: =+L7-L8 -> 34219.904
A10: Gastos VTs y Admin | B10: 4000 | C10: =+B10*(1+Supuestos!$B$4) -> 4188.3455 | D10: =+C10*(1+Supuestos!$B$4) -> 4385.5594 | E10: =+D10*(1+Supuestos!$B$4) -> 4592.0595 | F10: =+E10*(1+Supuestos!$B$4) -> 4808.2828 | G10: =+F10*2 -> 9616.5657 | H10: =+G10*(1+Supuestos!$B$4) -> 10069.375 | I10: =+H10*(1+Supuestos!$B$4) -> 10543.505 | J10: =+I10*(1+Supuestos!$B$4) -> 11039.96 | K10: =+J10*(1+Supuestos!$B$4) -> 11559.792 | L10: =+K10*(1+Supuestos!$B$4) -> 12104.1
A11: EBITDA | B11: =+B9-B10 -> 17600 | C11: =+C9-C10 -> 18428.72 | D11: =+D9-D10 -> 19296.461 | E11: =+E9-E10 -> 20205.062 | F11: =+F9-F10 -> 21156.444 | G11: =+G9-G10 -> 17570.746 | H11: =+H9-H10 -> 18398.089 | I11: =+I9-I10 -> 19264.388 | ... L11: =+L9-L10 -> 22115.804
A12: Depreciacion | B12: =+Supuestos!B11*Supuestos!B9 -> 3500 | C12: =+B12 -> 3500 | D12: =+C12 -> 3500 | E12: =+D12 -> 3500 | F12: =+E12 -> 3500 | G12: =+F12 -> 3500 | H12: =+G12 -> 3500 | I12: =+H12 -> 3500 | J12: =+I12 -> 3500 | ... L12: =+K12 -> 3500
A13: EBIT | B13: =+B11-B12 -> 14100 | C13: =+C11-C12 -> 14928.72 | D13: =+D11-D12 -> 15796.461 | E13: =+E11-E12 -> 16705.062 | F13: =+F11-F12 -> 17656.444 | G13: =+G11-G12 -> 14070.746 | H13: =+H11-H12 -> 14898.089 | I13: =+I11-I12 -> 15764.388 | ... L13: =+L11-L12 -> 18615.804
A14: Intereses | B14: 0 | C14: =+B29*B31 -> 0 | D14: =+C14 -> 0 | E14: =+D14 -> 0 | F14: =+E14 -> 0 | G14: =+F14 -> 0 | H14: 0 | I14: =+H14 -> 0 | J14: 0 | K14: 0 | L14: =+K14 -> 0
A15: EBT | B15: =+B13-B14 -> 14100 | C15: =+C13-C14 -> 14928.72 | D15: =+D13-D14 -> 15796.461 | E15: =+E13-E14 -> 16705.062 | F15: =+F13-F14 -> 17656.444 | G15: =+G13-G14 -> 14070.746 | H15: =+H13-H14 -> 14898.089 | I15: =+I13-I14 -> 15764.388 | ... L15: =+L13-L14 -> 18615.804
A16: Impuestos | B16: =+B15*0.3 -> 4230 | C16: =+C15*0.3 -> 4478.616 | D16: =+D15*0.3 -> 4738.9384 | E16: =+E15*0.3 -> 5011.5185 | F16: =+F15*0.3 -> 5296.9333 | G16: =+G15*0.3 -> 4221.2239 | H16: =+H15*0.3 -> 4469.4266 | I16: =+I15*0.3 -> 4729.3164 | ... L16: =+L15*0.3 -> 5584.7411
A17: Utilidad Neta | B17: =+B15-B16 -> 9870 | C17: =+C15-C16 -> 10450.104 | D17: =+D15-D16 -> 11057.523 | E17: =+E15-E16 -> 11693.543 | F17: =+F15-F16 -> 12359.511 | G17: =+G15-G16 -> 9849.5224 | H17: =+H15-H16 -> 10428.662 | I17: =+I15-I16 -> 11035.072 | ... L17: =+L15-L16 -> 13031.063
A19: Depreciación | B19: =+B12 -> 3500 | C19: =+C12 -> 3500 | D19: =+D12 -> 3500 | E19: =+E12 -> 3500 | F19: =+F12 -> 3500 | G19: =+G12 -> 3500 | H19: =+H12 -> 3500 | I19: =+I12 -> 3500 | ... L19: =+L12 -> 3500
A20: Cambio WC
A21: Flujo Operativo | B21: =+B17+B19-B20 -> 13370 | C21: =+C17+C19-C20 -> 13950.104 | D21: =+D17+D19-D20 -> 14557.523 | E21: =+E17+E19-E20 -> 15193.543 | F21: =+F17+F19-F20 -> 15859.511 | G21: =+G17+G19-G20 -> 13349.522 | H21: =+H17+H19-H20 -> 13928.662 | I21: =+I17+I19-I20 -> 14535.072 | ... L21: =+L17+L19-L20 -> 16531.063
A22: Deuda emison /Pago | C22: =+B29/5+C14 -> 0 | D22: =+C22 -> 0 | E22: =+D22 -> 0 | F22: =+E22 -> 0 | G22: 0 | H22: 0 | I22: =+H22 -> 0 | J22: =+I22 -> 0 | K22: =+J22 -> 0 | L22: =+K22 -> 0
A24: Flujo de Efectivo de Financiamineto | B24: =+B21-B22 -> 13370 | C24: =+C21-C22 -> 13950.104 | D24: =+D21-D22 -> 14557.523 | E24: =+E21-E22 -> 15193.543 | F24: =+F21-F22 -> 15859.511 | G24: =+G21-G22 -> 13349.522 | H24: =+H21-H22 -> 13928.662 | I24: =+I21-I22 -> 14535.072 | ... L24: =+L21-L22 -> 16531.063
A28: Deuda total | B28: 0 | C28: =+B28+B29-C22 -> 0 | D28: =+C28+C29-D22 -> 0 | E28: =+D28+D29-E22 -> 0 | F28: =+E28+E29-F22 -> 0 | G28: =+F28+F29-G22 -> 0 | H28: 0 | I28: 0 | J28: 0 | K28: 0 | L28: 0
A29: Nueva Deuda | B29: 0 | C29: 0 | D29: 0 | E29: 0 | F29: 0 | G29: 0 | H29: 0 | I29: 0 | J29: 0 | K29: 0 | L29: 0
A30: Deuda/Ebitda | B30: =+B28/B11 -> 0 | C30: =+C28/C11 -> 0 | D30: =+D28/D11 -> 0 | E30: =+E28/E11 -> 0 | F30: =+F28/F11 -> 0 | G30: =+G28/G11 -> 0 | H30: =+H28/H11 -> 0 | I30: =+I28/I11 -> 0 | ... L30: =+L28/L11 -> 0
A31: Intereses | B31: =+'EUR A MXN'!H7+Supuestos!B3 -> 0.04228452 | C31: =+B31 -> 0.04228452 | D31: =+C31 -> 0.04228452 | E31: =+D31 -> 0.04228452 | F31: =+E31 -> 0.04228452 | G31: =+F31 -> 0.04228452 | H31: =+G31 -> 0.04228452 | I31: =+H31 -> 0.04228452 | J31: =+I31 -> 0.04228452 | ... L31: =+K31 -> 0.04228452
A33: WC | B33: =-B24+B14+B22 -> -13370 | C33: =-C24+C14+C22 -> -13950.104 | D33: =-D24+D14+D22 -> -14557.523 | E33: =-E24+E14+E22 -> -15193.543 | F33: =-F24+F14+F22 -> -15859.511 | G33: =-G24+G14+G22 -> -13349.522 | H33: =-H24+H14+H22 -> -13928.662 | I33: =-I24+I14+I22 -> -14535.072 | ... L33: =-L24+L14+L22 -> -16531.063
A34: Cambio de WC
A36: Capex | B36: 0 | C36: 0 | D36: 0 | E36: 0 | F36: 0 | G36: 0 | H36: 0 | I36: 0 | J36: 0 | K36: 0 | L36: 0
A39: Free Cash Flow | B39: =+B24-B36 -> 13370 | C39: =+C24-C36 -> 13950.104 | D39: =+D24-D36 -> 14557.523 | E39: =+E24-E36 -> 15193.543 | F39: =+F24-F36 -> 15859.511 | G39: =+G24-G36 -> 13349.522 | H39: =+H24-H36 -> 13928.662 | I39: =+I24-I36 -> 14535.072 | ... L39: =+L24-L36 -> 16531.063
A40: TM | L40: =+L11*4 -> 88463.215
A41: FC +TV | B41: =+B39+B40 -> 13370 | C41: =+C39+C40 -> 13950.104 | D41: =+D39+D40 -> 14557.523 | E41: =+E39+E40 -> 15193.543 | F41: =+F39+F40 -> 15859.511 | G41: =+G39+G40 -> 13349.522 | H41: =+H39+H40 -> 13928.662 | I41: =+I39+I40 -> 14535.072 | ... L41: =+L39+L40 -> 104994.28
A43: NUEVO Requerimiento de Capital a Accionistas | B43: 0 | C43: 0 | D43: 0 | E43: 0 | F43: 0 | G43: 0 | H43: 0 | I43: 0 | J43: 0 | K43: 0 | L43: 0
A46: TIR | B46: =IRR(B41:L41) -> #NUM!

Sheet Con finacimiento
A1: Estados fiancieros Proyectados
B3: 2025 | C3: 2026 | D3: 2027 | E3: 2028 | F3: 2029 | G3: 2030 | H3: 2031 | I3: 2032 | J3: 2033 | K3: 2034 | L3: 2035 | O3: Unidades a comprar | P3: 1114
A4: Ingresos Base
A7: Ingreso | B7: =+'Industria Automotriz'!H38 -> 146990 | C7: =+'Industria Automotriz'!H39 -> 153911.22 | D7: =+'Industria Automotriz'!H40 -> 161158.34 | E7: =+'Industria Automotriz'!H41 -> 168746.7 | F7: =+'Industria Automotriz'!H42 -> 176692.37 | G7: =+'Industria Automotriz'!H43 -> 185012.17 | H7: =+'Industria Automotriz'!H44 -> 193723.73 | I7: =+'Industria Automotriz'!H45 -> 202845.47 | J7: =+'Industria Automotriz'!H46 -> 212396.73 | K7: =+'Industria Automotriz'!H47 -> 222397.72 | L7: =+'Industria Automotriz'!H48 -> 232869.62
A8: Costo de Venta | B8: =+B7*0.8 -> 117592 | C8: =+C7*0.8 -> 123128.98 | D8: =+D7*0.8 -> 128926.68 | E8: =+E7*0.8 -> 134997.36 | F8: =+F7*0.8 -> 141353.9 | G8: =+G7*0.8 -> 148009.74 | H8: =+H7*0.8 -> 154978.98 | I8: =+I7*0.8 -> 162276.38 | ... L8: =+L7*0.8 -> 186295.69
A9: Margen bruto | B9: =+B7-B8 -> 29398 | C9: =+C7-C8 -> 30782.245 | D9: =+D7-D8 -> 32231.669 | E9: =+E7-E8 -> 33749.341 | F9: =+F7-F8 -> 35338.475 | G9: =+G7-G8 -> 37002.435 | H9: =+H7-H8 -> 38744.745 | I9: =+I7-I8 -> 40569.094 | ... L9: =+L7-L8 -> 46573.923
A10: Gastos VTs y Admin | B10: 4000 | C10: =+B10*(1+Supuestos!$B$4) -> 4188.3455 | D10: =+C10*(1+Supuestos!$B$4) -> 4385.5594 | E10: =+D10*(1+Supuestos!$B$4) -> 4592.0595 | F10: =+E10*(1+Supuestos!$B$4) -> 4808.2828 | G10: =+F10*2 -> 9616.5657 | H10: =+G10*(1+Supuestos!$B$4) -> 10069.375 | I10: =+H10*(1+Supuestos!$B$4) -> 10543.505 | J10: =+I10*(1+Supuestos!$B$4) -> 11039.96 | K10: =+J10*(1+Supuestos!$B$4) -> 11559.792 | L10: =+K10*(1+Supuestos!$B$4) -> 12104.1
A11: EBITDA | B11: =+B9-B10 -> 25398 | C11: =+C9-C10 -> 26593.899 | D11: =+D9-D10 -> 27846.109 | E11: =+E9-E10 -> 29157.282 | F11: =+F9-F10 -> 30530.192 | G11: =+G9-G10 -> 27385.869 | H11: =+H9-H10 -> 28675.37 | I11: =+I9-I10 -> 30025.589 | ... L11: =+L9-L10 -> 34469.823
A12: Depreciacion | B12: =+Supuestos!B11*Supuestos!B9 -> 3500 | C12: =+B12 -> 3500 | D12: =+C12 -> 3500 | E12: =+D12 -> 3500 | F12: =+E12 -> 3500 | G12: =+F12 -> 3500 | H12: =+G12 -> 3500 | I12: =+H12 -> 3500 | J12: =+I12 -> 3500 | ... L12: =+K12 -> 3500
A13: EBIT | B13: =+B11-B12 -> 21898 | C13: =+C11-C12 -> 23093.899 | D13: =+D11-D12 -> 24346.109 | E13: =+E11-E12 -> 25657.282 | F13: =+F11-F12 -> 27030.192 | G13: =+G11-G12 -> 23885.869 | H13: =+H11-H12 -> 25175.37 | I13: =+I11-I12 -> 26525.589 | ... L13: =+L11-L12 -> 30969.823
A14: Intereses | B14: 0 | C14: =+B29*B31 -> 1789.9883 | D14: =+C14 -> 1789.9883 | E14: =+D14 -> 1789.9883 | F14: =+E14 -> 1789.9883 | G14: =+F14 -> 1789.9883 | H14: 0 | I14: =+H14 -> 0 | J14: 0 | K14: 0 | L14: =+K14 -> 0
A15: EBT | B15: =+B13-B14 -> 21898 | C15: =+C13-C14 -> 21303.911 | D15: =+D13-D14 -> 22556.121 | E15: =+E13-E14 -> 23867.293 | F15: =+F13-F14 -> 25240.204 | G15: =+G13-G14 -> 22095.881 | H15: =+H13-H14 -> 25175.37 | I15: =+I13-I14 -> 26525.589 | ... L15: =+L13-L14 -> 30969.823
A16: Impuestos | B16: =+B15*0.3 -> 6569.4 | C16: =+C15*0.3 -> 6391.1734 | D16: =+D15*0.3 -> 6766.8364 | E16: =+E15*0.3 -> 7160.188 | F16: =+F15*0.3 -> 7572.0611 | G16: =+G15*0.3 -> 6628.7643 | H16: =+H15*0.3 -> 7552.6111 | I16: =+I15*0.3 -> 7957.6768 | ... L16: =+L15*0.3 -> 9290.9468
A17: Utilidad Neta | B17: =+B15-B16 -> 15328.6 | C17: =+C15-C16 -> 14912.738 | D17: =+D15-D16 -> 15789.285 | E17: =+E15-E16 -> 16707.105 | F17: =+F15-F16 -> 17668.143 | G17: =+G15-G16 -> 15467.117 | H17: =+H15-H16 -> 17622.759 | I17: =+I15-I16 -> 18567.912 | ... L17: =+L15-L16 -> 21678.876
A19: Depreciación | B19: =+B12 -> 3500 | C19: =+C12 -> 3500 | D19: =+D12 -> 3500 | E19: =+E12 -> 3500 | F19: =+F12 -> 3500 | G19: =+G12 -> 3500 | H19: =+H12 -> 3500 | I19: =+I12 -> 3500 | ... L19: =+L12 -> 3500
A20: Cambio WC
A21: Flujo Operativo | B21: =+B17+B19-B20 -> 18828.6 | C21: =+C17+C19-C20 -> 18412.738 | D21: =+D17+D19-D20 -> 19289.285 | E21: =+E17+E19-E20 -> 20207.105 | F21: =+F17+F19-F20 -> 21168.143 | G21: =+G17+G19-G20 -> 18967.117 | H21: =+H17+H19-H20 -> 21122.759 | I21: =+I17+I19-I20 -> 22067.912 | ... L21: =+L17+L19-L20 -> 25178.876
A22: Deuda emison /Pago | C22: =+B29/5+C14 -> 10256.388 | D22: =+C22 -> 10256.388 | E22: =+D22 -> 10256.388 | F22: =+E22 -> 10256.388 | G22: 1162 | H22: 0 | I22: =+H22 -> 0 | J22: =+I22 -> 0 | K22: =+J22 -> 0 | L22: =+K22 -> 0
A24: Flujo de Efectivo de Financiamineto | B24: =+B21-B22 -> 18828.6 | C24: =+C21-C22 -> 8156.3495 | D24: =+D21-D22 -> 9032.8965 | E24: =+E21-E22 -> 9950.717 | F24: =+F21-F22 -> 10911.754 | G24: =+G21-G22 -> 17805.117 | H24: =+H21-H22 -> 21122.759 | I24: =+I21-I22 -> 22067.912 | ... L24: =+L21-L22 -> 25178.876
A28: Deuda total | B28: 0 | C28: =+B28+B29-C22 -> 32075.612 | D28: =+C28+C29-D22 -> 21819.223 | E28: =+D28+D29-E22 -> 11562.835 | F28: =+E28+E29-F22 -> 1306.4468 | G28: =+F28+F29-G22 -> 144.44685
A29: Nueva Deuda | B29: =+('Datos Proporcionados CL Circula'!B2+'Datos Proporcionados CL Circula'!B5)*'Con finacimiento'!P3 -> 42332 | C29: 0 | D29: 0 | E29: 0 | F29: 0 | G29: 0 | H29: 0 | I29: 0 | J29: 0 | K29: 0 | L29: 0
A30: Deuda/Ebitda | B30: =+B28/B11 -> 0 | C30: =+C28/C11 -> 1.2061267 | D30: =+D28/D11 -> 0.78356452 | E30: =+E28/E11 -> 0.39656767 | F30: =+F28/F11 -> 0.042791963 | G30: =+G28/G11 -> 0.0052745028 | H30: =+H28/H11 -> 0 | I30: =+I28/I11 -> 0 | ... L30: =+L28/L11 -> 0
A31: Intereses | B31: =+'EUR A MXN'!H7+Supuestos!B3 -> 0.04228452 | C31: =+B31 -> 0.04228452 | D31: =+C31 -> 0.04228452 | E31: =+D31 -> 0.04228452 | F31: =+E31 -> 0.04228452 | G31: =+F31 -> 0.04228452 | H31: =+G31 -> 0.04228452 | I31: =+H31 -> 0.04228452 | J31: =+I31 -> 0.04228452 | ... L31: =+K31 -> 0.04228452
A33: WC | B33: =-B24+B14+B22 -> -18828.6 | C33: =-C24+C14+C22 -> 3890.027 | D33: =-D24+D14+D22 -> 3013.48 | E33: =-E24+E14+E22 -> 2095.6596 | F33: =-F24+F14+F22 -> 1134.6224 | G33: =-G24+G14+G22 -> -14853.128 | H33: =-H24+H14+H22 -> -21122.759 | I33: =-I24+I14+I22 -> -22067.912 | ... L33: =-L24+L14+L22 -> -25178.876
A34: Cambio de WC
A36: Capex
A39: Free Cash Flow | B39: =+B24-B36 -> 18828.6 | C39: =+C24-C36 -> 8156.3495 | D39: =+D24-D36 -> 9032.8965 | E39: =+E24-E36 -> 9950.717 | F39: =+F24-F36 -> 10911.754 | G39: =+G24-G36 -> 17805.117 | H39: =+H24-H36 -> 21122.759 | I39: =+I24-I36 -> 22067.912 | ... L39: =+L24-L36 -> 25178.876
A40: TM | L40: =+L11*4 -> 137879.29
A41: FC +TV | B41: =+B39+B40 -> 18828.6 | C41: =+C39+C40 -> 8156.3495 | D41: =+D39+D40 -> 9032.8965 | E41: =+E39+E40 -> 9950.717 | F41: =+F39+F40 -> 10911.754 | G41: =+G39+G40 -> 17805.117 | H41: =+H39+H40 -> 21122.759 | I41: =+I39+I40 -> 22067.912 | ... L41: =+L39+L40 -> 163058.17
A43: NUEVO Requerimiento de Capital a Accionistas
A46: TIR

Sheet Con finacimiento PESIMISTA
A1: Estados fiancieros Proyectados
B3: 2025 | C3: 2026 | D3: 2027 | E3: 2028 | F3: 2029 | G3: 2030 | H3: 2031 | I3: 2032 | J3: 2033 | K3: 2034 | L3: 2035 | O3: Unidades a comprar | P3: 1114
A4: Ingresos Base
A7: Ingreso | B7: =+'Industria Automotriz'!H38 -> 146990 | C7: =+'Industria Automotriz'!I39 -> 150450.61 | D7: =+'Industria Automotriz'!I40 -> 153992.7 | E7: =+'Industria Automotriz'!I41 -> 157618.18 | F7: =+'Industria Automotriz'!I42 -> 161329.01 | G7: =+'Industria Automotriz'!I43 -> 165127.21 | H7: =+'Industria Automotriz'!I44 -> 169014.83 | I7: =+'Industria Automotriz'!I45 -> 172993.97 | J7: =+'Industria Automotriz'!I46 -> 177066.8 | K7: =+'Industria Automotriz'!I47 -> 181235.52 | L7: =+'Industria Automotriz'!I48 -> 185502.38
A8: Costo de Venta | B8: =+B7*0.8 -> 117592 | C8: =+C7*0.8 -> 120360.49 | D8: =+D7*0.8 -> 123194.16 | E8: =+E7*0.8 -> 126094.54 | F8: =+F7*0.8 -> 129063.21 | G8: =+G7*0.8 -> 132101.77 | H8: =+H7*0.8 -> 135211.86 | I8: =+I7*0.8 -> 138395.18 | ... L8: =+L7*0.8 -> 148401.9
A9: Margen bruto | B9: =+B7-B8 -> 29398 | C9: =+C7-C8 -> 30090.122 | D9: =+D7-D8 -> 30798.54 | E9: =+E7-E8 -> 31523.635 | F9: =+F7-F8 -> 32265.802 | G9: =+G7-G8 -> 33025.442 | H9: =+H7-H8 -> 33802.966 | I9: =+I7-I8 -> 34598.795 | ... L9: =+L7-L8 -> 37100.476
A10: Gastos VTs y Admin | B10: 4000 | C10: =+B10*(1+Supuestos!$B$4) -> 4188.3455 | D10: =+C10*(1+Supuestos!$B$4) -> 4385.5594 | E10: =+D10*(1+Supuestos!$B$4) -> 4592.0595 | F10: =+E10*(1+Supuestos!$B$4) -> 4808.2828 | G10: =+F10*2 -> 9616.5657 | H10: =+G10*(1+Supuestos!$B$4) -> 10069.375 | I10: =+H10*(1+Supuestos!$B$4) -> 10543.505 | J10: =+I10*(1+Supuestos!$B$4) -> 11039.96 | K10: =+J10*(1+Supuestos!$B$4) -> 11559.792 | L10: =+K10*(1+Supuestos!$B$4) -> 12104.1
A11: EBITDA | B11: =+B9-B10 -> 25398 | C11: =+C9-C10 -> 25901.777 | D11: =+D9-D10 -> 26412.98 | E11: =+E9-E10 -> 26931.576 | F11: =+F9-F10 -> 27457.519 | G11: =+G9-G10 -> 23408.876 | H11: =+H9-H10 -> 23733.591 | I11: =+I9-I10 -> 24055.29 | ... L11: =+L9-L10 -> 24996.376
A12: Depreciacion | B12: =+Supuestos!B11*Supuestos!B9 -> 3500 | C12: =+B12 -> 3500 | D12: =+C12 -> 3500 | E12: =+D12 -> 3500 | F12: =+E12 -> 3500 | G12: =+F12 -> 3500 | H12: =+G12 -> 3500 | I12: =+H12 -> 3500 | J12: =+I12 -> 3500 | ... L12: =+K12 -> 3500
A13: EBIT | B13: =+B11-B12 -> 21898 | C13: =+C11-C12 -> 22401.777 | D13: =+D11-D12 -> 22912.98 | E13: =+E11-E12 -> 23431.576 | F13: =+F11-F12 -> 23957.519 | G13: =+G11-G12 -> 19908.876 | H13: =+H11-H12 -> 20233.591 | I13: =+I11-I12 -> 20555.29 | ... L13: =+L11-L12 -> 21496.376
A14: Intereses | B14: 0 | C14: =+B29*B31 -> 1789.9883 | D14: =+C14 -> 1789.9883 | E14: =+D14 -> 1789.9883 | F14: =+E14 -> 1789.9883 | G14: =+F14 -> 1789.9883 | H14: 0 | I14: =+H14 -> 0 | J14: 0 | K14: 0 | L14: =+K14 -> 0
A15: EBT | B15: =+B13-B14 -> 21898 | C15: =+C13-C14 -> 20611.789 | D15: =+D13-D14 -> 21122.992 | E15: =+E13-E14 -> 21641.588 | F15: =+F13-F14 -> 22167.531 | G15: =+G13-G14 -> 18118.888 | H15: =+H13-H14 -> 20233.591 | I15: =+I13-I14 -> 20555.29 | ... L15: =+L13-L14 -> 21496.376
A16: Impuestos | B16: =+B15*0.3 -> 6569.4 | C16: =+C15*0.3 -> 6183.5366 | D16: =+D15*0.3 -> 6336.8976 | E16: =+E15*0.3 -> 6492.4763 | F16: =+F15*0.3 -> 6650.2593 | G16: =+G15*0.3 -> 5435.6663 | H16: =+H15*0.3 -> 6070.0772 | I16: =+I15*0.3 -> 6166.587 | ... L16: =+L15*0.3 -> 6448.9127
A17: Utilidad Neta | B17: =+B15-B16 -> 15328.6 | C17: =+C15-C16 -> 14428.252 | D17: =+D15-D16 -> 14786.094 | E17: =+E15-E16 -> 15149.111 | F17: =+F15-F16 -> 15517.272 | G17: =+G15-G16 -> 12683.221 | H17: =+H15-H16 -> 14163.514 | I17: =+I15-I16 -> 14388.703 | ... L17: =+L15-L16 -> 15047.463
A19: Depreciación | B19: =+B12 -> 3500 | C19: =+C12 -> 3500 | D19: =+D12 -> 3500 | E19: =+E12 -> 3500 | F19: =+F12 -> 3500 | G19: =+G12 -> 3500 | H19: =+H12 -> 3500 | I19: =+I12 -> 3500 | ... L19: =+L12 -> 3500
A20: Cambio WC
A21: Flujo Operativo | B21: =+B17+B19-B20 -> 18828.6 | C21: =+C17+C19-C20 -> 17928.252 | D21: =+D17+D19-D20 -> 18286.094 | E21: =+E17+E19-E20 -> 18649.111 | F21: =+F17+F19-F20 -> 19017.272 | G21: =+G17+G19-G20 -> 16183.221 | H21: =+H17+H19-H20 -> 17663.514 | I21: =+I17+I19-I20 -> 17888.703 | ... L21: =+L17+L19-L20 -> 18547.463
A22: Deuda emison /Pago | C22: =+B29/5+C14 -> 10256.388 | D22: =+C22 -> 10256.388 | E22: =+D22 -> 10256.388 | F22: =+E22 -> 10256.388 | G22: 1162 | H22: 0 | I22: =+H22 -> 0 | J22: =+I22 -> 0 | K22: =+J22 -> 0 | L22: =+K22 -> 0
A24: Flujo de Efectivo de Financiamineto | B24: =+B21-B22 -> 18828.6 | C24: =+C21-C22 -> 7671.8638 | D24: =+D21-D22 -> 8029.7061 | E24: =+E21-E22 -> 8392.723 | F24: =+F21-F22 -> 8760.8833 | G24: =+G21-G22 -> 15021.221 | H24: =+H21-H22 -> 17663.514 | I24: =+I21-I22 -> 17888.703 | ... L24: =+L21-L22 -> 18547.463
A28: Deuda total | B28: 0 | C28: =+B28+B29-C22 -> 32075.612 | D28: =+C28+C29-D22 -> 21819.223 | E28: =+D28+D29-E22 -> 11562.835 | F28: =+E28+E29-F22 -> 1306.4468 | G28: =+F28+F29-G22 -> 144.44685
A29: Nueva Deuda | B29: =+('Datos Proporcionados CL Circula'!B2+'Datos Proporcionados CL Circula'!B5)*'Con finacimiento PESIMISTA'!P3 -> 42332 | C29: 0 | D29: 0 | E29: 0 | F29: 0 | G29: 0 | H29: 0 | I29: 0 | J29: 0 | K29: 0 | L29: 0
A30: Deuda/Ebitda | B30: =+B28/B11 -> 0 | C30: =+C28/C11 -> 1.2383556 | D30: =+D28/D11 -> 0.82607957 | E30: =+E28/E11 -> 0.4293412 | F30: =+F28/F11 -> 0.047580659 | G30: =+G28/G11 -> 0.0061706015 | H30: =+H28/H11 -> 0 | I30: =+I28/I11 -> 0 | ... L30: =+L28/L11 -> 0
A31: Intereses | B31: =+'EUR A MXN'!H7+Supuestos!B3 -> 0.04228452 | C31: =+B31 -> 0.04228452 | D31: =+C31 -> 0.04228452 | E31: =+D31 -> 0.04228452 | F31: =+E31 -> 0.04228452 | G31: =+F31 -> 0.04228452 | H31: =+G31 -> 0.04228452 | I31: =+H31 -> 0.04228452 | J31: =+I31 -> 0.04228452 | ... L31: =+K31 -> 0.04228452
A33: WC | B33: =-B24+B14+B22 -> -18828.6 | C33: =-C24+C14+C22 -> 4374.5128 | D33: =-D24+D14+D22 -> 4016.6705 | E33: =-E24+E14+E22 -> 3653.6536 | F33: =-F24+F14+F22 -> 3285.4933 | G33: =-G24+G14+G22 -> -12069.233 | H33: =-H24+H14+H22 -> -17663.514 | I33: =-I24+I14+I22 -> -17888.703 | ... L33: =-L24+L14+L22 -> -18547.463
A34: Cambio de WC
A36: Capex
A39: Free Cash Flow | B39: =+B24-B36 -> 18828.6 | C39: =+C24-C36 -> 7671.8638 | D39: =+D24-D36 -> 8029.7061 | E39: =+E24-E36 -> 8392.723 | F39: =+F24-F36 -> 8760.8833 | G39: =+G24-G36 -> 15021.221 | H39: =+H24-H36 -> 17663.514 | I39: =+I24-I36 -> 17888.703 | ... L39: =+L24-L36 -> 18547.463
A40: TM | L40: =+L11*4 -> 99985.502
A41: FC +TV | B41: =+B39+B40 -> 18828.6 | C41: =+C39+C40 -> 7671.8638 | D41: =+D39+D40 -> 8029.7061 | E41: =+E39+E40 -> 8392.723 | F41: =+F39+F40 -> 8760.8833 | G41: =+G39+G40 -> 15021.221 | H41: =+H39+H40 -> 17663.514 | I41: =+I39+I40 -> 17888.703 | ... L41: =+L39+L40 -> 118532.97
A43: NUEVO Requerimiento de Capital a Accionistas
A46: TIR

Sheet Con finacimiento OPTIMISTA
A1: Estados fiancieros Proyectados
B3: 2025 | C3: 2026 | D3: 2027 | E3: 2028 | F3: 2029 | G3: 2030 | H3: 2031 | I3: 2032 | J3: 2033 | K3: 2034 | L3: 2035 | O3: Unidades a comprar | P3: 1114
A4: Ingresos Base
A7: Ingreso | B7: =+'Industria Automotriz'!H38 -> 146990 | C7: =+'Industria Automotriz'!J39 -> 153911.22 | D7: =+'Industria Automotriz'!J40 -> 164781.9 | E7: =+'Industria Automotriz'!J41 -> 176420.38 | F7: =+'Industria Automotriz'!J42 -> 188880.87 | G7: =+'Industria Automotriz'!J43 -> 202221.44 | H7: =+'Industria Automotriz'!J44 -> 216504.24 | I7: =+'Industria Automotriz'!J45 -> 231795.84 | J7: =+'Industria Automotriz'!J46 -> 248167.48 | K7: =+'Industria Automotriz'!J47 -> 265695.43 | L7: =+'Industria Automotriz'!J48 -> 284461.38
A8: Costo de Venta | B8: =+B7*0.8 -> 117592 | C8: =+C7*0.8 -> 123128.98 | D8: =+D7*0.8 -> 131825.52 | E8: =+E7*0.8 -> 141136.3 | F8: =+F7*0.8 -> 151104.69 | G8: =+G7*0.8 -> 161777.15 | H8: =+H7*0.8 -> 173203.4 | I8: =+I7*0.8 -> 185436.67 | ... L8: =+L7*0.8 -> 227569.1
A9: Margen bruto | B9: =+B7-B8 -> 29398 | C9: =+C7-C8 -> 30782.245 | D9: =+D7-D8 -> 32956.381 | E9: =+E7-E8 -> 35284.075 | F9: =+F7-F8 -> 37776.173 | G9: =+G7-G8 -> 40444.287 | H9: =+H7-H8 -> 43300.849 | I9: =+I7-I8 -> 46359.168 | ... L9: =+L7-L8 -> 56892.276
A10: Gastos VTs y Admin | B10: 4000 | C10: =+B10*(1+Supuestos!$B$4) -> 4188.3455 | D10: =+C10*(1+Supuestos!$B$4) -> 4385.5594 | E10: =+D10*(1+Supuestos!$B$4) -> 4592.0595 | F10: =+E10*(1+Supuestos!$B$4) -> 4808.2828 | G10: =+F10*2 -> 9616.5657 | H10: =+G10*(1+Supuestos!$B$4) -> 10069.375 | I10: =+H10*(1+Supuestos!$B$4) -> 10543.505 | J10: =+I10*(1+Supuestos!$B$4) -> 11039.96 | K10: =+J10*(1+Supuestos!$B$4) -> 11559.792 | L10: =+K10*(1+Supuestos!$B$4) -> 12104.1
A11: EBITDA | B11: =+B9-B10 -> 25398 | C11: =+C9-C10 -> 26593.899 | D11: =+D9-D10 -> 28570.821 | E11: =+E9-E10 -> 30692.016 | F11: =+F9-F10 -> 32967.89 | G11: =+G9-G10 -> 30827.722 | H11: =+H9-H10 -> 33231.474 | I11: =+I9-I10 -> 35815.663 | ... L11: =+L9-L10 -> 44788.175
A12: Depreciacion | B12: =+Supuestos!B11*Supuestos!B9 -> 3500 | C12: =+B12 -> 3500 | D12: =+C12 -> 3500 | E12: =+D12 -> 3500 | F12: =+E12 -> 3500 | G12: =+F12 -> 3500 | H12: =+G12 -> 3500 | I12: =+H12 -> 3500 | J12: =+I12 -> 3500 | ... L12: =+K12 -> 3500
A13: EBIT | B13: =+B11-B12 -> 21898 | C13: =+C11-C12 -> 23093.899 | D13: =+D11-D12 -> 25070.821 | E13: =+E11-E12 -> 27192.016 | F13: =+F11-F12 -> 29467.89 | G13: =+G11-G12 -> 27327.722 | H13: =+H11-H12 -> 29731.474 | I13: =+I11-I12 -> 32315.663 | ... L13: =+L11-L12 -> 41288.175
A14: Intereses | B14: 0 | C14: =+B29*B31 -> 1789.9883 | D14: =+C14 -> 1789.9883 | E14: =+D14 -> 1789.9883 | F14: =+E14 -> 1789.9883 | G14: =+F14 -> 1789.9883 | H14: 0 | I14: =+H14 -> 0 | J14: 0 | K14: 0 | L14: =+K14 -> 0
A15: EBT | B15: =+B13-B14 -> 21898 | C15: =+C13-C14 -> 21303.911 | D15: =+D13-D14 -> 23280.833 | E15: =+E13-E14 -> 25402.027 | F15: =+F13-F14 -> 27677.902 | G15: =+G13-G14 -> 25537.733 | H15: =+H13-H14 -> 29731.474 | I15: =+I13-I14 -> 32315.663 | ... L15: =+L13-L14 -> 41288.175
A16: Impuestos | B16: =+B15*0.3 -> 6569.4 | C16: =+C15*0.3 -> 6391.1734 | D16: =+D15*0.3 -> 6984.25 | E16: =+E15*0.3 -> 7620.6082 | F16: =+F15*0.3 -> 8303.3706 | G16: =+G15*0.3 -> 7661.32 | H16: =+H15*0.3 -> 8919.4422 | I16: =+I15*0.3 -> 9694.6989 | ... L16: =+L15*0.3 -> 12386.453
A17: Utilidad Neta | B17: =+B15-B16 -> 15328.6 | C17: =+C15-C16 -> 14912.738 | D17: =+D15-D16 -> 16296.583 | E17: =+E15-E16 -> 17781.419 | F17: =+F15-F16 -> 19374.532 | G17: =+G15-G16 -> 17876.413 | H17: =+H15-H16 -> 20812.032 | I17: =+I15-I16 -> 22620.964 | ... L17: =+L15-L16 -> 28901.723
A19: Depreciación | B19: =+B12 -> 3500 | C19: =+C12 -> 3500 | D19: =+D12 -> 3500 | E19: =+E12 -> 3500 | F19: =+F12 -> 3500 | G19: =+G12 -> 3500 | H19: =+H12 -> 3500 | I19: =+I12 -> 3500 | ... L19: =+L12 -> 3500
A20: Cambio WC
A21: Flujo Operativo | B21: =+B17+B19-B20 -> 18828.6 | C21: =+C17+C19-C20 -> 18412.738 | D21: =+D17+D19-D20 -> 19796.583 | E21: =+E17+E19-E20 -> 21281.419 | F21: =+F17+F19-F20 -> 22874.532 | G21: =+G17+G19-G20 -> 21376.413 | H21: =+H17+H19-H20 -> 24312.032 | I21: =+I17+I19-I20 -> 26120.964 | ... L21: =+L17+L19-L20 -> 32401.723
A22: Deuda emison /Pago | C22: =+B29/5+C14 -> 10256.388 | D22: =+C22 -> 10256.388 | E22: =+D22 -> 10256.388 | F22: =+E22 -> 10256.388 | G22: 1162 | H22: 0 | I22: =+H22 -> 0 | J22: =+I22 -> 0 | K22: =+J22 -> 0 | L22: =+K22 -> 0
A24: Flujo de Efectivo de Financiamineto | B24: =+B21-B22 -> 18828.6 | C24: =+C21-C22 -> 8156.3495 | D24: =+D21-D22 -> 9540.1949 | E24: =+E21-E22 -> 11025.031 | F24: =+F21-F22 -> 12618.143 | G24: =+G21-G22 -> 20214.413 | H24: =+H21-H22 -> 24312.032 | I24: =+I21-I22 -> 26120.964 | ... L24: =+L21-L22 -> 32401.723
A28: Deuda total | B28: 0 | C28: =+B28+B29-C22 -> 32075.612 | D28: =+C28+C29-D22 -> 21819.223 | E28: =+D28+D29-E22 -> 11562.835 | F28: =+E28+E29-F22 -> 1306.4468 | G28: =+F28+F29-G22 -> 144.44685
A29: Nueva Deuda | B29: =+('Datos Proporcionados CL Circula'!B2+'Datos Proporcionados CL Circula'!B5)*'Con finacimiento OPTIMISTA'!P3 -> 42332 | C29: 0 | D29: 0 | E29: 0 | F29: 0 | G29: 0 | H29: 0 | I29: 0 | J29: 0 | K29: 0 | L29: 0
A30: Deuda/Ebitda | B30: =+B28/B11 -> 0 | C30: =+C28/C11 -> 1.2061267 | D30: =+D28/D11 -> 0.76368905 | E30: =+E28/E11 -> 0.37673756 | F30: =+F28/F11 -> 0.039627857 | G30: =+G28/G11 -> 0.0046856153 | H30: =+H28/H11 -> 0 | I30: =+I28/I11 -> 0 | ... L30: =+L28/L11 -> 0
A31: Intereses | B31: =+'EUR A MXN'!H7+Supuestos!B3 -> 0.04228452 | C31: =+B31 -> 0.04228452 | D31: =+C31 -> 0.04228452 | E31: =+D31 -> 0.04228452 | F31: =+E31 -> 0.04228452 | G31: =+F31 -> 0.04228452 | H31: =+G31 -> 0.04228452 | I31: =+H31 -> 0.04228452 | J31: =+I31 -> 0.04228452 | ... L31: =+K31 -> 0.04228452
A33: WC | B33: =-B24+B14+B22 -> -18828.6 | C33: =-C24+C14+C22 -> 3890.027 | D33: =-D24+D14+D22 -> 2506.1816 | E33: =-E24+E14+E22 -> 1021.3457 | F33: =-F24+F14+F22 -> -571.76664 | G33: =-G24+G14+G22 -> -17262.425 | H33: =-H24+H14+H22 -> -24312.032 | I33: =-I24+I14+I22 -> -26120.964 | ... L33: =-L24+L14+L22 -> -32401.723
A34: Cambio de WC
A36: Capex
A39: Free Cash Flow | B39: =+B24-B36 -> 18828.6 | C39: =+C24-C36 -> 8156.3495 | D39: =+D24-D36 -> 9540.1949 | E39: =+E24-E36 -> 11025.031 | F39: =+F24-F36 -> 12618.143 | G39: =+G24-G36 -> 20214.413 | H39: =+H24-H36 -> 24312.032 | I39: =+I24-I36 -> 26120.964 | ... L39: =+L24-L36 -> 32401.723
A40: TM | L40: =+L11*4 -> 179152.7
A41: FC +TV | B41: =+B39+B40 -> 18828.6 | C41: =+C39+C40 -> 8156.3495 | D41: =+D39+D40 -> 9540.1949 | E41: =+E39+E40 -> 11025.031 | F41: =+F39+F40 -> 12618.143 | G41: =+G39+G40 -> 20214.413 | H41: =+H39+H40 -> 24312.032 | I41: =+I39+I40 -> 26120.964 | ... L41: =+L39+L40 -> 211554.42
A43: NUEVO Requerimiento de Capital a Accionistas
A46: TIR
